ValueError: 1 columns passed, passed data had 2 columns
AssertionError                            Traceback (most recent call last)
~/.local/lib/python3.7/site-packages/pandas/core/internals/construction.py in _finalize_columns_and_data(content, columns, dtype)
    905     try:
--> 906         columns = _validate_or_indexify_columns(contents, columns)
    907     except AssertionError as err:

~/.local/lib/python3.7/site-packages/pandas/core/internals/construction.py in _validate_or_indexify_columns(content, columns)
    954             raise AssertionError(
--> 955                 f"{len(columns)} columns passed, passed data had "
    956                 f"{len(content)} columns"

AssertionError: 1 columns passed, passed data had 2 columns

The above exception was the direct cause of the following exception:

ValueError                                Traceback (most recent call last)
/tmp/ipykernel_113/1215835711.py in <module>
      1 if __name__ == "__main__":
----> 2     excecute_process()

/tmp/ipykernel_113/4117894532.py in excecute_process()
     35 
     36         # Parsear (horizontal)
---> 37         df = pfh.read_file(str(local_pdf_path))
     38         print("Aqui vienen los types:-----------------")
     39         print("\n--- TIPOS DEL DATAFRAME ---")

~/competitor_data/purina_file_horizontal.py in read_file(file_path)
    150 
    151     # (a) Extraer tablas
--> 152     tables = extract_main_table(file_path)
    153     if not tables:
    154         print("[WARN] No se extrajo tabla principal, devolviendo vacÃ­o")

~/competitor_data/purina_file_horizontal.py in extract_main_table(file_path)
     88     headers = [h.lower().strip().replace(" ", "_") for h in raw_headers]
     89     data = rows[1:]
---> 90     df = pd.DataFrame(data, columns=headers)
     91     return [df]
     92 

~/.local/lib/python3.7/site-packages/pandas/core/frame.py in __init__(self, data, index, columns, dtype, copy)
    698                         columns,
    699                         index,  # type: ignore[arg-type]
--> 700                         dtype,
    701                     )
    702                     mgr = arrays_to_mgr(

~/.local/lib/python3.7/site-packages/pandas/core/internals/construction.py in nested_data_to_arrays(data, columns, index, dtype)
    481         columns = ensure_index(data[0]._fields)
    482 
--> 483     arrays, columns = to_arrays(data, columns, dtype=dtype)
    484     columns = ensure_index(columns)
    485 

~/.local/lib/python3.7/site-packages/pandas/core/internals/construction.py in to_arrays(data, columns, dtype)
    805         arr = _list_to_arrays(data)
    806 
--> 807     content, columns = _finalize_columns_and_data(arr, columns, dtype)
    808     return content, columns
    809 

~/.local/lib/python3.7/site-packages/pandas/core/internals/construction.py in _finalize_columns_and_data(content, columns, dtype)
    907     except AssertionError as err:
    908         # GH#26429 do not raise user-facing AssertionError
--> 909         raise ValueError(err) from err
    910 
    911     if len(contents) and contents[0].dtype == np.object_:

ValueError: 1 columns passed, passed data had 2 columns
